<?xml version="1.0" ?>
<!-- =================================================================================== -->
<!-- |    This document was autogenerated by xacro from indy.urdf.xacro                | -->
<!-- |    EDITING THIS FILE BY HAND IS NOT RECOMMENDED                                 | -->
<!-- =================================================================================== -->
<robot name="indy">
  <material name="black">
    <color rgba="0.0 0.0 0.0 1.0"/>
  </material>
  <material name="blue">
    <color rgba="0.0 0.0 0.8 1.0"/>
  </material>
  <material name="green">
    <color rgba="0.0 0.8 0.0 1.0"/>
  </material>
  <material name="icon_green">
    <color rgba="0.596078431372549 0.7764705882352941 0.3843137254901961 1.0"/>
  </material>
  <material name="icon_grey">
    <color rgba="0.2 0.2 0.2 1.0"/>
  </material>
  <material name="indy_white">
    <color rgba="0.8941176470588236 0.8941176470588236 0.8941176470588236 1.0"/>
  </material>
  <material name="grey">
    <color rgba="0.2 0.2 0.2 1.0"/>
  </material>
  <material name="orange">
    <color rgba="1.0 0.4235294117647059 0.0392156862745098 1.0"/>
  </material>
  <material name="brown">
    <color rgba="0.8705882352941177 0.8117647058823529 0.7647058823529411 1.0"/>
  </material>
  <material name="red">
    <color rgba="0.8 0.0 0.0 1.0"/>
  </material>
  <material name="white">
    <color rgba="1.0 1.0 1.0 1.0"/>
  </material>
  <material name="metal">
    <color rgba="0.768627450980392 0.749019607843137 0.729411764705882 1"/>
  </material>
  <material name="metal_grey">
    <color rgba="0.501960784313725 0.501960784313725 0.501960784313725 1"/>
  </material>
  <material name="metal_white">
    <color rgba="0.866666666666667 0.866666666666667 0.890196078431373 1"/>
  </material>
  <link name="world"/>
  <link name="link0">
    <visual>
      <origin rpy="0 0 0" xyz="0 0 0"/>
      <geometry>
        <mesh filename="./Nuri3s_0.stl"/>
      </geometry>
      <material name="indy_white"/>
    </visual>
    <collision>
      <origin rpy="0 0 0" xyz="0 0 0"/>
      <geometry>
        <mesh filename="./Nuri3s_0.stl"/>
      </geometry>
    </collision>
    <inertial>
      <mass value="0.7"/>
      <origin rpy="0 0 0" xyz="-0.0001269426 0.0005108801 0.0488997513"/>
      <inertia ixx="0.0018791124" ixy="-1.296e-07" ixz="-1.158e-06" iyy="0.0018240876" iyz="-5.3898e-05" izz="0.0023673372"/>
    </inertial>
  </link>
  <link name="link1">
    <visual>
      <origin rpy="0 0 0" xyz="0 0 0"/>
      <geometry>
        <mesh filename="./Nuri3s_1.stl"/>
      </geometry>
      <material name="indy_white"/>
    </visual>
    <collision>
      <origin rpy="0 0 0" xyz="0 0 0"/>
      <geometry>
        <mesh filename="./Nuri3s_1.stl"/>
      </geometry>
    </collision>
    <inertial>
      <mass value="4,0"/>
      <origin rpy="0 0 0" xyz="2.2204e-05 -0.008727763 0.22543341"/>
      <inertia ixx="0.0256432056" ixy="1.356e-07" ixz="-4.6008e-06" iyy="0.02511687" iyz="-0.0021156948" izz="0.0050187096"/>
    </inertial>
  </link>
  <link name="link2">
    <visual>
      <origin rpy="0 0 0" xyz="0 0 0"/>
      <geometry>
        <mesh filename="./Nuri3s_2.stl"/>
      </geometry>
      <material name="indy_white"/>
    </visual>
    <collision>
      <origin rpy="0 0 0" xyz="0 0 0"/>
      <geometry>
        <mesh filename="./Nuri3s_2.stl"/>
      </geometry>
    </collision>
    <inertial>
      <mass value="4.5"/>
      <origin rpy="0 0 0" xyz="0.018500507 -0.068861752 0.142338346"/>
      <inertia ixx="0.07356876" ixy="0.0005969232" ixz="0.0103854408" iyy="0.0737158296" iyz="-0.0003617904" izz="0.0107195388"/>
    </inertial>
  </link>
  <link name="link3">
    <visual>
      <origin rpy="0 0 0" xyz="0 0 0"/>
      <geometry>
        <mesh filename="./Nuri3s_3.stl"/>
      </geometry>
      <material name="indy_white"/>
    </visual>
    <collision>
      <origin rpy="0 0 0" xyz="0 0 0"/>
      <geometry>
        <mesh filename="./Nuri3s_3.stl"/>
      </geometry>
    </collision>
    <inertial>
      <mass value="2.5"/>
      <origin rpy="0 0 0" xyz="0.025033992 0.011525635 0.041307263"/>
      <inertia ixx="0.0077879832" ixy="-0.0006300936" ixz="0.0020521464" iyy="0.0084282504" iyz="-0.0009818712" izz="0.0039553944"/>
    </inertial>
  </link>
  <link name="link4">
    <visual>
      <origin rpy="0 0 0" xyz="0 0 0"/>
      <geometry>
        <mesh filename="./Nuri3s_4.stl"/>
      </geometry>
      <material name="indy_white"/>
    </visual>
    <collision>
      <origin rpy="0 0 0" xyz="0 0 0"/>
      <geometry>
        <mesh filename="./Nuri3s_4.stl"/>
      </geometry>
    </collision>
    <inertial>
      <mass value="2.5"/>
      <origin rpy="0 0 0" xyz="-2.5487e-05 -0.01092259 -0.071267109"/>
      <inertia ixx="0.0159838224" ixy="-2.22e-06" ixz="1.0404e-06" iyy="0.0150238704" iyz="-0.001726728" izz="0.0033459372"/>
    </inertial>
  </link>
  <link name="link5">
    <visual>
      <origin rpy="0 0 0" xyz="0 0 0"/>
      <geometry>
        <mesh filename="./Nuri3s_5.stl"/>
      </geometry>
      <material name="indy_white"/>
    </visual>
    <collision>
      <origin rpy="0 0 0" xyz="0 0 0"/>
      <geometry>
        <mesh filename="./Nuri3s_5.stl"/>
      </geometry>
    </collision>
    <inertial>
      <mass value="2.5"/>
      <origin rpy="0 0 0" xyz="2.911e-06 0.029173125 0.007018623"/>
      <inertia ixx="0.00603915" ixy="-7.29e-06" ixz="-1.5516e-06" iyy="0.0031373016" iyz="-0.0003979776" izz="0.0047337636"/>
    </inertial>
  </link>
  <link name="link6">
    <visual>
      <origin rpy="0 0 0" xyz="0 0 0"/>
      <geometry>
        <mesh filename="./Nuri3s_6.stl"/>
      </geometry>
      <material name="indy_white"/>
    </visual>
    <collision>
      <origin rpy="0 0 0" xyz="0 0 0"/>
      <geometry>
        <mesh filename="./Nuri3s_6.stl"/>
      </geometry>
    </collision>
    <inertial>
      <mass value="1.5"/>
      <origin rpy="0 0 0" xyz="7.2631e-05 7.9047e-05 -0.044852927"/>
      <inertia ixx="0.0011964192" ixy="-1.6512e-06" ixz="1.0764e-06" iyy="0.001203036" iyz="1.8972e-06" izz="0.0005375376"/>
    </inertial>
  </link>
  <link name="tcp"/>
  <!-- joints -->
  <joint name="global" type="fixed">
    <origin rpy="0 0 0" xyz="0 0 0"/>
    <parent link="world"/>
    <!--world-->
    <child link="link0"/>
  </joint>
  <joint name="joint0" type="revolute">
    <parent link="link0"/>
    <child link="link1"/>
    <origin rpy="0.0                         0.0                         0.0" xyz="0.0                          0.0                          0.09"/>
    <axis xyz="0 0 1"/>
    <limit effort="431.97" lower="-6.283185307179586" upper="6.283185307179586" velocity="3.141592653589793"/>
  </joint>
  <joint name="joint1" type="revolute">
    <parent link="link1"/>
    <child link="link2"/>
    <origin rpy="1.570796327                         0.0                         0.0" xyz="0.0                          -0.04                          0.223"/>
    <axis xyz="0 0 1"/>
    <limit effort="431.97" lower="-2.705260340591211" upper="2.443460952792061" velocity="3.141592653589793"/>
  </joint>
  <joint name="joint2" type="revolute">
    <parent link="link2"/>
    <child link="link3"/>
    <origin rpy="0.0                         0.0                         0.0" xyz="0.05023                          0.2900135                          0.0"/>
    <axis xyz="0 0 1"/>
    <limit effort="197.23" lower="-3.0543261909900767" upper="2.356194490192345" velocity="3.141592653589793"/>
  </joint>
  <joint name="joint3" type="revolute">
    <parent link="link3"/>
    <child link="link4"/>
    <origin rpy="-1.570796327                         0.0                         0.0" xyz="-0.05                          0.085                          -0.04"/>
    <axis xyz="0 0 1"/>
    <limit effort="79.79" lower="-6.283185307179586" upper="6.283185307179586" velocity="3.141592653589793"/>
  </joint>
  <joint name="joint4" type="revolute">
    <parent link="link4"/>
    <child link="link5"/>
    <origin rpy="1.570796327                         0.0                         0.0" xyz="0.0                          0.07                          0.2050424"/>
    <axis xyz="0 0 1"/>
    <limit effort="79.79" lower="-6.283185307179586" upper="6.283185307179586" velocity="3.141592653589793"/>
  </joint>
  <joint name="joint5" type="revolute">
    <parent link="link5"/>
    <child link="link6"/>
    <origin rpy="-1.570796327                         0.0                         0.0" xyz="0.0                          0.075                          -0.066"/>
    <axis xyz="0 0 1"/>
    <limit effort="79.79" lower="-6.283185307179586" upper="6.283185307179586" velocity="3.141592653589793"/>
  </joint>
  <joint name="tcp" type="fixed">
    <parent link="link6"/>
    <child link="tcp"/>
    <!-- <origin xyz="0 0 0.06" rpy="0 0 0"/> -->
    <origin rpy="0.0                         0.0                         0.0" xyz="0.0                          0.0                          0.0285"/>
  </joint>
  <ros2_control name="indy" type="system">
    <hardware>
      <plugin>fake_components/GenericSystem</plugin>
      <!-- <param name="fake_sensor_commands">${fake_sensor_commands}</param> -->
      <param name="state_following_offset">0.0</param>
    </hardware>
    <joint name="joint0">
      <command_interface name="position">
        <param name="min">{-2*pi}</param>
        <param name="max">{2*pi}</param>
      </command_interface>
      <command_interface name="velocity">
        <param name="min">-3.15</param>
        <param name="max">3.15</param>
      </command_interface>
      <!-- <state_interface name="position"/> -->
      <state_interface name="position">
        <param name="initial_value">0.0</param>
      </state_interface>
      <!-- <state_interface name="velocity"/> -->
      <state_interface name="velocity">
        <param name="initial_value">0.0</param>
      </state_interface>
      <state_interface name="effort"/>
    </joint>
    <joint name="joint1">
      <command_interface name="position">
        <param name="min">{-2*pi}</param>
        <param name="max">{2*pi}</param>
      </command_interface>
      <command_interface name="velocity">
        <param name="min">-3.15</param>
        <param name="max">3.15</param>
      </command_interface>
      <!-- <state_interface name="position"/> -->
      <state_interface name="position">
        <param name="initial_value">0.0</param>
      </state_interface>
      <!-- <state_interface name="velocity"/> -->
      <state_interface name="velocity">
        <param name="initial_value">0.0</param>
      </state_interface>
      <state_interface name="effort"/>
    </joint>
    <joint name="joint2">
      <command_interface name="position">
        <param name="min">{-2*pi}</param>
        <param name="max">{2*pi}</param>
      </command_interface>
      <command_interface name="velocity">
        <param name="min">-3.15</param>
        <param name="max">3.15</param>
      </command_interface>
      <!-- <state_interface name="position"/> -->
      <state_interface name="position">
        <param name="initial_value">-1.57</param>
      </state_interface>
      <!-- <state_interface name="velocity"/> -->
      <state_interface name="velocity">
        <param name="initial_value">0.0</param>
      </state_interface>
      <state_interface name="effort"/>
    </joint>
    <joint name="joint3">
      <command_interface name="position">
        <param name="min">{-2*pi}</param>
        <param name="max">{2*pi}</param>
      </command_interface>
      <command_interface name="velocity">
        <param name="min">-3.15</param>
        <param name="max">3.15</param>
      </command_interface>
      <!-- <state_interface name="position"/> -->
      <state_interface name="position">
        <param name="initial_value">0.0</param>
      </state_interface>
      <!-- <state_interface name="velocity"/> -->
      <state_interface name="velocity">
        <param name="initial_value">0.0</param>
      </state_interface>
      <state_interface name="effort"/>
    </joint>
    <joint name="joint4">
      <command_interface name="position">
        <param name="min">{-2*pi}</param>
        <param name="max">{2*pi}</param>
      </command_interface>
      <command_interface name="velocity">
        <param name="min">-3.15</param>
        <param name="max">3.15</param>
      </command_interface>
      <!-- <state_interface name="position"/> -->
      <state_interface name="position">
        <param name="initial_value">-1.57</param>
      </state_interface>
      <!-- <state_interface name="velocity"/> -->
      <state_interface name="velocity">
        <param name="initial_value">0.0</param>
      </state_interface>
      <state_interface name="effort"/>
    </joint>
    <joint name="joint5">
      <command_interface name="position">
        <param name="min">{-2*pi}</param>
        <param name="max">{2*pi}</param>
      </command_interface>
      <command_interface name="velocity">
        <param name="min">-3.15</param>
        <param name="max">3.15</param>
      </command_interface>
      <!-- <state_interface name="position"/> -->
      <state_interface name="position">
        <param name="initial_value">0.0</param>
      </state_interface>
      <!-- <state_interface name="velocity"/> -->
      <state_interface name="velocity">
        <param name="initial_value">0.0</param>
      </state_interface>
      <state_interface name="effort"/>
    </joint>
  </ros2_control>
  <!-- Add URDF transmission elements (for ros_control) -->
  <!-- <xacro:indy_transmission prefix="${prefix}" hw_interface="${transmission_hw_interface}" indy_type="${indy_type}"/> -->
</robot>
